Workbook

Sheet Septiembre 2026
A1: KUGELMAN ACADEMY | CONTROL DE CLASES MUESTRA | SEPTIEMBRE 2026
A4: Fecha clase | B4: Alumno | C4: Contacto | D4: Categoría | E4: Edad | F4: Idioma | G4: Canal | H4: Hora | I4: Resultado | J4: Motivo no inscripción | K4: Observaciones
A5: 2026-09-01 | B5: Erick Samuel Rivera Rivera | C5: 4441920798 | D5: Kids | E5: 7 | F5: Inglés | G5: Facebook | H5: 5:00 pm | I5: Inscrito | K5: Facebook
A6: 2026-09-01 | B6: Melissa Rivera Rivera | C6: 4441920798 | D6: Kids | E6: 7 | F6: Inglés | G6: Facebook | H6: 5:00 pm | I6: Inscrito | K6: Facebook
A7: 2026-09-01 | B7: Mateo Romero | C7: 771 525 2088 | D7: Kids | E7: 11 | F7: Inglés | G7: Whatsaap | H7: 5:00 pm | I7: Show | J7: Ubicación
A8: 2026-09-02 | B8: Ximena Gamboa | C8: 7751142632 | D8: College | E8: 18 | F8: Inglés | G8: Facebook | H8: 5:00 pm | I8: Show | J8: Pendiente de decisión | K8: Erika Flores Barrera
A9: 2026-09-02 | B9: Dego Marquez Pedroza | D9: Junior | E9: 16 | F9: Inglés | G9: Facebook | H9: 4:00 pm | I9: Inscrito
A10: 2026-09-02 | B10: Laura Lizet Pedroza | D10: College | E10: 35 | F10: Inglés | G10: Facebook | H10: 4:00 pm | I10: Inscrito
A11: 2026-09-02 | B11: Dylan Eduardo Martes Pedrosa | D11: Junior | E11: 12 | F11: Inglés | G11: Facebook | H11: 4:00 pm | I11: Inscrito
A12: 2026-09-02 | B12: Emiliano Bahena | C12: 5524008650 | D12: Kids | E12: 8 | F12: Inglés | G12: Facebook | H12: 6:00 pm | I12: Inscrito
A13: 2026-09-02 | B13: Renata Bahena | C13: 5524008650 | D13: Parenthood | E13: 6 | F13: Inglés | G13: Facebook | H13: 6:00 pm | I13: Inscrito
A14: 2026-09-03 | B14: Lia Jardines Angeles | C14: 771 181 5517 | D14: Kids | E14: 8 | F14: Inglés | G14: Facebook | H14: 5:00 pm | I14: No asistió | K14: EN ESPERA
A15: 2026-09-03 | B15: Natalia Avila | C15: 7714450790 | D15: Kids | E15: 9 | F15: Inglés | G15: Facebook | H15: 5:00 pm | I15: No asistió | K15: EN ESPERA
A16: 2026-09-03 | B16: Leonardo Avila | C16: 7714450790 | D16: Parenthood | E16: 5 | F16: Inglés | G16: Facebook | H16: 5:00 pm | I16: No asistió | K16: EN ESPERA
A17: 2026-09-03 | B17: Ximena Aguirre | C17: 771 194 5558 | D17: Kids | E17: 10 | F17: Inglés | G17: Facebook | H17: 5:00 pm | I17: Inscrito
A18: 2026-09-03 | B18: Farid Mateo Jardines Angeles | C18: 771 181 5517 | D18: Junior | E18: 12 | F18: Inglés | G18: Facebook | H18: 6:00 pm | I18: No asistió | K18: EN ESPERA
A19: 2026-09-03 | B19: Valentina Miranda Vazquez Balderas | C19: 525585293517 | D19: Junior | E19: 14 | F19: Inglés | G19: Facebook | H19: 7:00 pm | I19: Show | J19: Precio | K19: VIRTUAL
A20: 2026-09-03 | B20: Zoe Hernandez Garcia | C20: 771 191 8111 | D20: Junior | E20: 15 | F20: Inglés | G20: Facebook | H20: 7:00 PM | I20: Show | J20: Sin respuesta | K20: VIRTUAL
A21: 2026-09-04 | B21: Sharon | C21: 5524008650 | D21: College | E21: 39 | F21: Inglés | G21: Instagram | H21: 10:00 am | I21: Show | J21: Motivos personales
A22: 2026-09-04 | B22: JACQUELINE Hernandez Morales | C22: 5548973202 | D22: College | E22: 44 | F22: Inglés | G22: Recomendación | H22: 10:00 am | I22: Inscrito
A23: 2026-09-04 | B23: Nayeli | C23: 7714450790 | D23: College | E23: 41 | F23: Inglés | G23: Facebook | H23: 10:00 am | I23: No asistió
A24: 2026-09-05 | B24: SAMANTHA BAUTISTA RAMIREZ | C24: 5568052558 | D24: Kids | E24: 7 | F24: Inglés | G24: Sitio | H24: 11:00 am | I24: Inscrito
A25: 2026-09-07 | B25: Daniela Valeria Hernández Pineda | C25: 5579509282 | D25: Kids | E25: 11 | F25: Inglés | G25: Facebook | H25: 9:00 am | I25: No asistió | K25: FACEBOOK
A26: 2026-09-07 | B26: Yatsiri Alexandra Sanchez Hernandez | C26: 7713759048 | D26: Junior | E26: 12 | F26: Inglés | G26: Facebook | H26: 4:00 pm | I26: No asistió
A27: 2026-09-07 | B27: Maria Fernanda Hernández Pineda | C27: 5579509282 | D27: Kids | E27: 7 | F27: Inglés | G27: Facebook | H27: 4:00 pm | I27: No asistió
A28: 2026-09-07 | B28: Axel Enciso Enciso | C28: 5518484384 | D28: College | E28: 20 | F28: Inglés | G28: Facebook | H28: 7:00 PM | I28: Inscrito
A29: 2026-09-08 | B29: Paola Fuentes Hernandez | C29: 55 4654 8040 | D29: College | E29: 30 | F29: Inglés | G29: Whatsaap | H29: 12:00 pm | I29: No asistió
A30: 2026-09-08 | B30: Juan Mohedano Olivares | C30: 771 176 4720 | D30: College | E30: 29 | F30: Inglés | G30: Facebook | H30: 12:00 pm | I30: Inscrito
A31: 2026-09-08 | B31: Maximo Bastian Rodriguez Carbajal | C31: 7714983578 | D31: Parenthood | E31: 4 | F31: Francés | G31: Whatsaap | H31: 6:00 pm | I31: Show | J31: Sin respuesta
A32: 2026-09-08 | B32: Apolo Leonardo Rodriguez Carbajal | C32: 7714983578 | D32: Parenthood | E32: 5 | F32: Francés | G32: Whatsaap | H32: 6:00 pm | I32: Show | J32: Sin respuesta
A33: 2026-09-09 | B33: Zoemy Samara Santander Herrera | C33: 7717508346 | D33: Parenthood | E33: 6 | F33: Inglés | G33: Facebook | H33: 4:00 pm | I33: Inscrito
A34: 2026-09-09 | B34: Darlene Fatima Santander Herrera | C34: 7717508346 | D34: Kids | E34: 9 | F34: Inglés | G34: Facebook | H34: 4:00 pm | I34: Inscrito
A35: 2026-09-09 | B35: Roxana Hernandez Torres | C35: 55 4356 4382 | D35: Junior | E35: 14 | F35: Inglés | G35: Instagram | H35: 4:00 pm | I35: Show | J35: Precio
A36: 2026-09-09 | B36: Heliana García Vazquez | C36: 7712541790 | D36: Junior | E36: 13 | F36: Inglés | G36: Facebook | H36: 4:00 pm | I36: Inscrito | K36: FACEBOOK
A37: 2026-09-09 | B37: Mateo García Vazquez | C37: 7712541790 | D37: Junior | E37: 14 | F37: Inglés | G37: Facebook | H37: 4:00 pm | I37: Inscrito | K37: FACEBOOK
A38: 2026-09-10 | B38: Fredy Adán Vega Hernández | C38: 7712980301 | D38: College | E38: 29 | F38: Inglés | G38: Facebook | H38: 12:00 pm | I38: Show | J38: Horarios
A39: REVISAR FECHA | B39: Francisco Morales Dominguez | C39: 7711975432 | D39: College | E39: 23 | F39: Inglés | G39: Facebook | H39: 6:00 pm | I39: Show | J39: Ubicación
A40: REVISAR FECHA | B40: Nikol Peña Estrada | C40: 7712409020 | D40: Junior | E40: 13 | F40: Inglés | G40: Facebook | H40: 6:00 pm | I40: Inscrito
A41: REVISAR FECHA | B41: Maria Luisa Hernandez | C41: 55 4356 4382 | D41: College | E41: 48 | F41: Inglés | G41: Facebook | H41: 10:00 am | I41: No asistió
A42: 2026-09-11 | B42: Juan Cruz Rodríguez | C42: 7751259674 | D42: College | E42: 53 | F42: Inglés | G42: Facebook | H42: 10:00 am | I42: Show | J42: Sin respuesta
...

Sheet Reporte Septiembre
A1: KUGELMAN ACADEMY| REPORTE DE CLASES MUESTRA | SEPTIEMBRE 2026
A3: Reporte independiente · se actualiza automáticamente desde la hoja de registros del mes
A5: Indicador | B5: Resultado
A6: Clases registradas | B6: =COUNTA('Septiembre 2026'!B5:B500) -> 82
A7: Inscritos | B7: =COUNTIF('Septiembre 2026'!I5:I500,"Inscrito") -> 32
A8: Show (no inscrito) | B8: =COUNTIF('Septiembre 2026'!I5:I500,"Show") -> 30
A9: No asistió | B9: =COUNTIF('Septiembre 2026'!I5:I500,"No asistió") -> 19
A10: Cita pendiente | B10: =COUNTIF('Septiembre 2026'!I5:I500,"Cita") -> 0
A11: Por revisar | B11: =COUNTIF('Septiembre 2026'!I5:I500,"Revisar") -> 1
A12: Decisiones confirmadas | B12: =B7+B8 -> 62
A13: Conversión de asistentes con decisión | B13: =IFERROR(B7/B12,0) -> 0.51612903
A14: Asistencia a clase | B14: =IFERROR(B12/(B12+B9),0) -> 0.7654321
A17: Resultado tras la clase | B17: Alumnos
A18: Se inscribió | B18: =B7 -> 32
A19: No se inscribió | B19: =B8 -> 30
A22: Motivo de no inscripción | B22: No. Prospectos
A23: Precio | B23: =COUNTIFS('Septiembre 2026'!I5:I500,"Show",'Septiembre 2026'!J5:J500,A23) -> 3
A24: Horarios | B24: =COUNTIFS('Septiembre 2026'!I5:I500,"Show",'Septiembre 2026'!J5:J500,A24) -> 6
A25: Ubicación | B25: =COUNTIFS('Septiembre 2026'!I5:I500,"Show",'Septiembre 2026'!J5:J500,A25) -> 6
A26: Metodología | B26: =COUNTIFS('Septiembre 2026'!I5:I500,"Show",'Septiembre 2026'!J5:J500,A26) -> 0
A27: No le interesó | B27: =COUNTIFS('Septiembre 2026'!I5:I500,"Show",'Septiembre 2026'!J5:J500,A27) -> 0
A28: Prefiere otra opción | B28: =COUNTIFS('Septiembre 2026'!I5:I500,"Show",'Septiembre 2026'!J5:J500,A28) -> 0
A29: Motivos personales | B29: =COUNTIFS('Septiembre 2026'!I5:I500,"Show",'Septiembre 2026'!J5:J500,A29) -> 2
A30: Sin respuesta | B30: =COUNTIFS('Septiembre 2026'!I5:I500,"Show",'Septiembre 2026'!J5:J500,A30) -> 9
A31: Pendiente de decisión | B31: =COUNTIFS('Septiembre 2026'!I5:I500,"Show",'Septiembre 2026'!J5:J500,A31) -> 4
A32: Inscripción pospuesta | B32: =COUNTIFS('Septiembre 2026'!I5:I500,"Show",'Septiembre 2026'!J5:J500,A32) -> 0

Sheet Octubre 2026
A1: KUGELMAN | CONTROL DE CLASES MUESTRA | OCTUBRE 2026
A4: Fecha clase | B4: Prospecto | C4: Contacto | D4: Categoría | E4: Edad | F4: Idioma | G4: Nivel | H4: Canal Contacto | I4: Hora | J4: Resultado | K4: Motivo no inscripción
A5: 46296 | B5: Claudia Perez | C5: 7711518732 | D5: College | E5: 29 | F5: Inglés | H5: Facebook | I5: 6:00 pm | J5: Show | K5: Sin respuesta
A6: 46297 | B6: Irma Luna Lira | C6: 7711859473 | D6: College | E6: 77 | F6: Inglés | H6: Facebook | I6: 10:00 am | J6: Inscrito
A7: 46298 | B7: Carlos Torres Marín | C7: 771 397 6155 | D7: Junior | E7: 12 | F7: Inglés | H7: Facebook | I7: 9:00 am | J7: Inscrito
A8: 46300 | B8: Emily Camacho Bello | C8: 7712931010 | D8: Junior | E8: 15 | F8: Inglés | H8: Facebook | I8: 4:00pm | J8: Inscrito
A9: 46300 | B9: Nidia Lizbeth | C9: 7711566420 | D9: College | E9: 24 | F9: Inglés | H9: Facebook | I9: 4:00 pm | J9: Inscrito
A10: 46300 | B10: Pía Bello Martínez | C10: 7712931010 | D10: Kids | E10: 7 | F10: Inglés | H10: Facebook | I10: 4:00pm | J10: Inscrito
A11: 46301 | B11: Aline Gutierrez | C11: 7711231297 | D11: College | E11: 22 | F11: Inglés | H11: Instagram | I11: 12:00 pm | J11: No asistió
A12: 46301 | B12: Beatriz Narváez | C12: 7711367215 | D12: College | E12: 32 | F12: Inglés | H12: Facebook | I12: 3:00 pm | J12: Inscrito
A13: 46301 | B13: Heiden Slim | C13: 5543168832 | D13: College | E13: 24 | F13: Inglés | H13: Instagram | I13: 3:00 pm | J13: No asistió
A14: 46301 | B14: Jorge Orozco | C14: 771 109 5087 | D14: College | E14: 40 | F14: Inglés | H14: Instagram | I14: 9:00 am | J14: No asistió
A15: 46301 | B15: Ximena Sanchez Bautista | C15: 7711914489 | D15: College | E15: 35 | F15: Inglés | H15: Whatsaap | I15: 12:00 pm | J15: Show | K15: Inscripción pospuesta
A16: 46303 | B16: Andy | C16: 663 110 5777 | D16: College | E16: 18 | F16: Inglés | H16: Facebook | I16: 6:00 pm | J16: No asistió
A17: 46303 | B17: Camila García romero | C17: 7711279246 | D17: Kids | E17: 11 | F17: Inglés | H17: Facebook | I17: 4:00 pm | J17: Inscrito
A18: 46303 | B18: Emilia García romero | C18: 7711279246 | D18: Kids | E18: 12 | F18: Inglés | H18: Facebook | I18: 4:00 pm | J18: Inscrito
A19: 46303 | B19: Jorge | C19: 663 110 5777 | D19: College | E19: 35 | F19: Inglés | H19: Facebook | I19: 6:00 pm | J19: No asistió
A20: 46303 | B20: Vicenta Aragon | C20: 7717427010 | D20: College | E20: 49 | F20: Inglés | H20: Facebook | I20: 6:00 pm | J20: No asistió
A21: 46304 | B21: Said Emmanuel Hernandez | C21: 7713229658 | D21: College | E21: 22 | F21: Inglés | H21: Instagram | I21: 4:00 pm | J21: Show | K21: Inscripción pospuesta
A22: 46307 | B22: Herlinda Guadalupe Zapataq Molina | C22: 5644941722 | D22: Kids | E22: 9 | F22: Inglés | H22: Facebook | I22: 6:00 pm | J22: Show | K22: Horarios
A23: 46307 | B23: Santiago mercado | C23: 7712164572 | D23: Junior | E23: 17 | F23: Inglés | H23: Facebook | I23: 5:00 pm | J23: Inscrito
A24: 46308 | B24: Aida | C24: 5517795341 | D24: College | E24: 55 | F24: Francés | I24: 6:00 pm | J24: No asistió
A25: 46308 | B25: Alexandra Rueda Cruz | C25: 7711780143 | D25: Junior | E25: 17 | F25: Inglés | H25: Facebook | I25: 9:00 am | J25: Inscrito
A26: 46308 | B26: Lianne | C26: 5517795341 | D26: Junior | E26: 15 | F26: Francés | I26: 6:00 pm | J26: No asistió
A27: 46308 | B27: Norberto Eligio Cordova López | C27: 7711235436 | D27: Junior | E27: 12 | F27: Inglés | H27: Whatsaap | I27: 5:00 pm | J27: No asistió
A28: 46308 | B28: Ramón Francisco Rueda Cruz | C28: 7713641316 | D28: Junior | E28: 15 | F28: Inglés | H28: Facebook | I28: 9:00 am | J28: Inscrito
A29: 46308 | B29: Yara | C29: 5517795341 | D29: College | E29: 18 | F29: Francés | I29: 6:00 pm | J29: No asistió
A30: 46310 | B30: Citlali Perez Vargas | C30: 4423200655 | D30: College | E30: 33 | F30: Inglés | H30: Instagram | I30: 12:00 pm | J30: Show | K30: Horarios
A31: 46310 | B31: Eduardo Hernandez | C31: 7711056674 | D31: College | E31: 24 | F31: Inglés | H31: Facebook | I31: 6:00 pm | J31: Inscrito
A32: 46310 | B32: Carlos Villalva | C32: 7712727928 | D32: Junior | E32: 12 | F32: Inglés | H32: Whatsaap | I32: 4:00 pm | J32: Show | K32: Horarios
A33: 46310 | B33: Sthivf Islas Gomez | D33: College | E33: 28 | F33: Inglés | H33: Facebook | I33: 6:00 pm | J33: No asistió
A34: 46310 | B34: Valentina Villalba | C34: 7712727928 | D34: Junior | E34: 14 | F34: Inglés | H34: Whatsaap | I34: 4:00 pm | J34: Show | K34: Horarios
A35: 46310 | B35: Karen García | C35: 7713595300 | D35: College | E35: 34 | F35: Inglés | H35: Whatsaap | I35: 6:00 pm | J35: No asistió
A36: 46311 | B36: Brisa Azul Salgado Anastasio | C36: 7721251065 | D36: Junior | E36: 14 | F36: Inglés | H36: Whatsaap | I36: 4:00 pm | J36: Show | K36: Pendiente de decisión
A37: 46311 | B37: Fernanda Trejo | C37: 7717820054 | D37: Junior | E37: 15 | F37: Inglés | H37: Whatsaap | I37: 4:00 pm | J37: No asistió
A38: 46314 | B38: Carlos Mercado | C38: 771 216 4572 | D38: College | E38: 38 | F38: Inglés | H38: Whatsaap | I38: 7 p.m. | J38: Inscrito
A39: 46314 | B39: Kim Yetzali | C39: 7711578877 | D39: Junior | E39: 14 | F39: Inglés | H39: Facebook | I39: 4 p.m. | J39: Show | K39: Sin respuesta
A40: 46315 | B40: Luna Danae Ángeles Islas | C40: 7711834181 | D40: Junior | E40: 12 | F40: Inglés | H40: Whatsaap | I40: 4:00 p.m. | J40: Inscrito | K40: Pendiente de decisión
A41: 46315 | B41: Dylan santiago lopez valverde | C41: 7712091673 | D41: Kids | E41: 11 | F41: Inglés | H41: Facebook | I41: 4 pm | J41: Inscrito | K41: Pendiente de decisión
A42: 46317 | B42: Eduardo Alexis Vallejo Salazar | C42: 7712940466 | D42: College | E42: 18 | F42: Inglés | G42: Intermedio | H42: Whatsaap | I42: 9 a.m. | J42: Show | K42: Pendiente de decisión
...

Sheet Reporte Octubre
A1: KUGELMAN ACADEMY| REPORTE DE CLASES MUESTRA | OCTUBRE 2026
A3: Reporte independiente · se actualiza automáticamente desde la hoja de registros del mes
A4: Fecha inicial | B4: 46296
A5: Fecha final | B5: 46318
A6: Indicador | B6: Resultado
A7: Clases registradas | B7: =COUNTIFS('Octubre 2026'!A:A,">="&$B$4,'Octubre 2026'!A:A,"<="&$B$5) -> 43
A8: Inscritos | B8: =COUNTIFS('Octubre 2026'!A:A,">="&$B$4,'Octubre 2026'!A:A,"<="&$B$5,'Octubre 2026'!J:J,"Inscrito") -> 15
A9: Show (no inscrito) | B9: =COUNTIFS('Octubre 2026'!A:A,">="&$B$4,'Octubre 2026'!A:A,"<="&$B$5,'Octubre 2026'!J:J,"Show") -> 11
A10: No asistió | B10: =COUNTIFS('Octubre 2026'!A:A,">="&$B$4,'Octubre 2026'!A:A,"<="&$B$5,'Octubre 2026'!J:J,"No asistió") -> 16
A11: Cita pendiente | B11: =COUNTIFS('Octubre 2026'!A:A,">="&$B$4,'Octubre 2026'!A:A,"<="&$B$5,'Octubre 2026'!J:J,"Cita") -> 1
A12: Por revisar | B12: =COUNTIFS('Octubre 2026'!A:A,">="&$B$4,'Octubre 2026'!A:A,"<="&$B$5,'Octubre 2026'!J:J,"Revisar") -> 0
A13: Decisiones confirmadas | B13: =B8+B9 -> 26
A14: Conversión de asistentes con decisión | B14: =IFERROR(B8/B13,0) -> 0.57692308
A15: Asistencia a clase | B15: =IFERROR(B13/(B13+B10),0) -> 0.61904762
A16: Clases Efectivas | B16: =SUM(B8+B9) -> 26
A18: Resultado tras la clase | B18: Alumnos
A19: Se inscribió | B19: =B8 -> 15
A20: No se inscribió | B20: =B9 -> 11
A23: Motivo de no inscripción | B23: No. Prospectos
A24: Precio | B24: =COUNTIFS('Octubre 2026'!J:J,"Show",'Octubre 2026'!K:K,A24,'Octubre 2026'!A:A,">="&$B$4,'Octubre 2026'!A:A,"<="&$B$5) -> 0
A25: Horarios | B25: =COUNTIFS('Octubre 2026'!J:J,"Show",'Octubre 2026'!K:K,A25,'Octubre 2026'!A:A,">="&$B$4,'Octubre 2026'!A:A,"<="&$B$5) -> 4
A26: Ubicación | B26: =COUNTIFS('Octubre 2026'!J:J,"Show",'Octubre 2026'!K:K,A26,'Octubre 2026'!A:A,">="&$B$4,'Octubre 2026'!A:A,"<="&$B$5) -> 0
A27: Metodología | B27: =COUNTIFS('Octubre 2026'!J:J,"Show",'Octubre 2026'!K:K,A27,'Octubre 2026'!A:A,">="&$B$4,'Octubre 2026'!A:A,"<="&$B$5) -> 0
A28: No le interesó | B28: =COUNTIFS('Octubre 2026'!J:J,"Show",'Octubre 2026'!K:K,A28,'Octubre 2026'!A:A,">="&$B$4,'Octubre 2026'!A:A,"<="&$B$5) -> 0
A29: Prefiere otra opción | B29: =COUNTIFS('Octubre 2026'!J:J,"Show",'Octubre 2026'!K:K,A29,'Octubre 2026'!A:A,">="&$B$4,'Octubre 2026'!A:A,"<="&$B$5) -> 0
A30: Motivos personales | B30: =COUNTIFS('Octubre 2026'!J:J,"Show",'Octubre 2026'!K:K,A30,'Octubre 2026'!A:A,">="&$B$4,'Octubre 2026'!A:A,"<="&$B$5) -> 0
A31: Sin respuesta | B31: =COUNTIFS('Octubre 2026'!J:J,"Show",'Octubre 2026'!K:K,A31,'Octubre 2026'!A:A,">="&$B$4,'Octubre 2026'!A:A,"<="&$B$5) -> 2
A32: Pendiente de decisión | B32: =COUNTIFS('Octubre 2026'!J:J,"Show",'Octubre 2026'!K:K,A32,'Octubre 2026'!A:A,">="&$B$4,'Octubre 2026'!A:A,"<="&$B$5) -> 2
A33: Inscripción pospuesta | B33: =COUNTIFS('Octubre 2026'!J:J,"Show",'Octubre 2026'!K:K,A33,'Octubre 2026'!A:A,">="&$B$4,'Octubre 2026'!A:A,"<="&$B$5) -> 2
A39: Categoría | B39: No. Alumnos
A40: Parenthood
A41: Kids
A42: Junior
A43: College
A44: Certifications

Sheet Noviembre 2026
A1: KUGELMAN | CONTROL DE CLASES MUESTRA | NOVIEMBRE 2026
A4: Fecha clase | B4: Prospecto | C4: Contacto | D4: Categoría | E4: Edad | F4: Idioma | G4: Nivel | H4: Canal Contacto | I4: Hora | J4: Resultado | K4: Motivo no inscripción
A5: 46333 | B5: Emir | C5: 771 144 2627 | D5: Parenthood | E5: 9 | F5: Inglés | G5: Basico | H5: Facebook | J5: Cita | M5: 1
A6: 46333 | B6: Yarentzy | C6: 771 144 2627 | D6: Kids | E6: 12 | F6: Inglés | G6: Principiante | H6: Facebook | J6: Cita | M6: 2
M7: 3
M8: 4
M9: 5
M10: 6
M11: 7
M12: 8
M13: 9
M14: 10
M15: 11
M16: 12
M17: 13
M18: 14
... M77: 73

Sheet Reporte Noviembre
A1: KUGELMAN ACADEMY| REPORTE DE CLASES MUESTRA | NOVIEMBRE 2026
A3: Reporte independiente · se actualiza automáticamente desde la hoja de registros del mes
A4: Fecha inicial | B4: 46327
A5: Fecha final | B5: 46296
A6: Indicador | B6: Resultado
A7: Clases registradas | B7: =COUNTIFS('Noviembre 2026'!A:A,">="&$B$4,'Noviembre 2026'!A:A,"<="&$B$5) -> 0
A8: Inscritos | B8: =COUNTIFS('Noviembre 2026'!A:A,">="&$B$4,'Noviembre 2026'!A:A,"<="&$B$5,'Noviembre 2026'!J:J,"Inscrito") -> 0
A9: Show (no inscrito) | B9: =COUNTIFS('Noviembre 2026'!A:A,">="&$B$4,'Noviembre 2026'!A:A,"<="&$B$5,'Noviembre 2026'!J:J,"Show") -> 0
A10: No asistió | B10: =COUNTIFS('Noviembre 2026'!A:A,">="&$B$4,'Noviembre 2026'!A:A,"<="&$B$5,'Noviembre 2026'!J:J,"No asistió") -> 0
A11: Cita pendiente | B11: =COUNTIFS('Noviembre 2026'!A:A,">="&$B$4,'Noviembre 2026'!A:A,"<="&$B$5,'Noviembre 2026'!J:J,"Cita") -> 0
A12: Por revisar | B12: =COUNTIFS('Noviembre 2026'!A:A,">="&$B$4,'Noviembre 2026'!A:A,"<="&$B$5,'Noviembre 2026'!J:J,"Revisar") -> 0
A13: Decisiones confirmadas | B13: =B8+B9 -> 0
A14: Conversión de asistentes con decisión | B14: =IFERROR(B8/B13,0) -> 0
A15: Asistencia a clase | B15: =IFERROR(B13/(B13+B10),0) -> 0
A16: Clases Efectivas | B16: =SUM(B8+B9) -> 0
A18: Resultado tras la clase | B18: Alumnos
A19: Se inscribió | B19: =B8 -> 0
A20: No se inscribió | B20: =B9 -> 0
A23: Motivo de no inscripción | B23: No. Prospectos
A24: Precio | B24: =COUNTIFS('Octubre 2026'!J:J,"Show",'Octubre 2026'!K:K,A24,'Octubre 2026'!A:A,">="&$B$4,'Octubre 2026'!A:A,"<="&$B$5) -> 0
A25: Horarios | B25: =COUNTIFS('Octubre 2026'!J:J,"Show",'Octubre 2026'!K:K,A25,'Octubre 2026'!A:A,">="&$B$4,'Octubre 2026'!A:A,"<="&$B$5) -> 0
A26: Ubicación | B26: =COUNTIFS('Octubre 2026'!J:J,"Show",'Octubre 2026'!K:K,A26,'Octubre 2026'!A:A,">="&$B$4,'Octubre 2026'!A:A,"<="&$B$5) -> 0
A27: Metodología | B27: =COUNTIFS('Octubre 2026'!J:J,"Show",'Octubre 2026'!K:K,A27,'Octubre 2026'!A:A,">="&$B$4,'Octubre 2026'!A:A,"<="&$B$5) -> 0
A28: No le interesó | B28: =COUNTIFS('Octubre 2026'!J:J,"Show",'Octubre 2026'!K:K,A28,'Octubre 2026'!A:A,">="&$B$4,'Octubre 2026'!A:A,"<="&$B$5) -> 0
A29: Prefiere otra opción | B29: =COUNTIFS('Octubre 2026'!J:J,"Show",'Octubre 2026'!K:K,A29,'Octubre 2026'!A:A,">="&$B$4,'Octubre 2026'!A:A,"<="&$B$5) -> 0
A30: Motivos personales | B30: =COUNTIFS('Octubre 2026'!J:J,"Show",'Octubre 2026'!K:K,A30,'Octubre 2026'!A:A,">="&$B$4,'Octubre 2026'!A:A,"<="&$B$5) -> 0
A31: Sin respuesta | B31: =COUNTIFS('Octubre 2026'!J:J,"Show",'Octubre 2026'!K:K,A31,'Octubre 2026'!A:A,">="&$B$4,'Octubre 2026'!A:A,"<="&$B$5) -> 0
A32: Pendiente de decisión | B32: =COUNTIFS('Octubre 2026'!J:J,"Show",'Octubre 2026'!K:K,A32,'Octubre 2026'!A:A,">="&$B$4,'Octubre 2026'!A:A,"<="&$B$5) -> 0
A33: Inscripción pospuesta | B33: =COUNTIFS('Octubre 2026'!J:J,"Show",'Octubre 2026'!K:K,A33,'Octubre 2026'!A:A,">="&$B$4,'Octubre 2026'!A:A,"<="&$B$5) -> 0
A39: Categoría | B39: No. Alumnos
A40: Parenthood
A41: Kids
A42: Junior
A43: College
A44: Certifications
